Workbook

Sheet Summary
A1: RBI Website (stg-rbi.webc.in) — Test Case Summary
A2: All figures below are formulas over the "Test Cases" sheet — they update as you set Status.
A4: Total test cases | B4: =COUNTA('Test Cases'!A2:A269) -> 268
A5: Automated | B5: =COUNTIF('Test Cases'!L2:L269,"Automated") -> 185
A6: Manual | B6: =COUNTIF('Test Cases'!L2:L269,"Manual") -> 83
A7: Automation coverage | B7: =IF(B4=0,0,B5/B4) -> 0.69029851
A8: Executed (Pass + Fail + Blocked) | B8: =COUNTIF('Test Cases'!N2:N269,"Pass")+COUNTIF('Test Cases'!N2:N269,"Fail")+COUNTIF('Test Cases'!N2:N269,"Blocked") -> 0
A9: Pass rate (of executed) | B9: =IF(B8=0,0,COUNTIF('Test Cases'!N2:N269,"Pass")/B8) -> 0
A10: Known defects logged | B10: =COUNTA('Known Defects'!A2:A16) -> 15
A12: By Module
A13: By Module | B13: Total | C13: Automated | D13: Not Run | E13: Pass | F13: Fail | G13: Blocked | H13: N/A
A14: Access & Environment | B14: =COUNTIF('Test Cases'!B2:B269,A14) -> 8 | C14: =COUNTIFS('Test Cases'!B2:B269,A14,'Test Cases'!L2:L269,"Automated") -> 1 | D14: =COUNTIFS('Test Cases'!B2:B269,A14,'Test Cases'!N2:N269,"Not Run") -> 8 | E14: =COUNTIFS('Test Cases'!B2:B269,A14,'Test Cases'!N2:N269,"Pass") -> 0 | F14: =COUNTIFS('Test Cases'!B2:B269,A14,'Test Cases'!N2:N269,"Fail") -> 0 | G14: =COUNTIFS('Test Cases'!B2:B269,A14,'Test Cases'!N2:N269,"Blocked") -> 0 | H14: =COUNTIFS('Test Cases'!B2:B269,A14,'Test Cases'!N2:N269,"N/A") -> 0
A15: Header | B15: =COUNTIF('Test Cases'!B2:B269,A15) -> 20 | C15: =COUNTIFS('Test Cases'!B2:B269,A15,'Test Cases'!L2:L269,"Automated") -> 14 | D15: =COUNTIFS('Test Cases'!B2:B269,A15,'Test Cases'!N2:N269,"Not Run") -> 20 | E15: =COUNTIFS('Test Cases'!B2:B269,A15,'Test Cases'!N2:N269,"Pass") -> 0 | F15: =COUNTIFS('Test Cases'!B2:B269,A15,'Test Cases'!N2:N269,"Fail") -> 0 | G15: =COUNTIFS('Test Cases'!B2:B269,A15,'Test Cases'!N2:N269,"Blocked") -> 0 | H15: =COUNTIFS('Test Cases'!B2:B269,A15,'Test Cases'!N2:N269,"N/A") -> 0
A16: Search | B16: =COUNTIF('Test Cases'!B2:B269,A16) -> 24 | C16: =COUNTIFS('Test Cases'!B2:B269,A16,'Test Cases'!L2:L269,"Automated") -> 14 | D16: =COUNTIFS('Test Cases'!B2:B269,A16,'Test Cases'!N2:N269,"Not Run") -> 24 | E16: =COUNTIFS('Test Cases'!B2:B269,A16,'Test Cases'!N2:N269,"Pass") -> 0 | F16: =COUNTIFS('Test Cases'!B2:B269,A16,'Test Cases'!N2:N269,"Fail") -> 0 | G16: =COUNTIFS('Test Cases'!B2:B269,A16,'Test Cases'!N2:N269,"Blocked") -> 0 | H16: =COUNTIFS('Test Cases'!B2:B269,A16,'Test Cases'!N2:N269,"N/A") -> 0
A17: Accessibility Toolbar | B17: =COUNTIF('Test Cases'!B2:B269,A17) -> 18 | C17: =COUNTIFS('Test Cases'!B2:B269,A17,'Test Cases'!L2:L269,"Automated") -> 13 | D17: =COUNTIFS('Test Cases'!B2:B269,A17,'Test Cases'!N2:N269,"Not Run") -> 18 | E17: =COUNTIFS('Test Cases'!B2:B269,A17,'Test Cases'!N2:N269,"Pass") -> 0 | F17: =COUNTIFS('Test Cases'!B2:B269,A17,'Test Cases'!N2:N269,"Fail") -> 0 | G17: =COUNTIFS('Test Cases'!B2:B269,A17,'Test Cases'!N2:N269,"Blocked") -> 0 | H17: =COUNTIFS('Test Cases'!B2:B269,A17,'Test Cases'!N2:N269,"N/A") -> 0
A18: Language | B18: =COUNTIF('Test Cases'!B2:B269,A18) -> 6 | C18: =COUNTIFS('Test Cases'!B2:B269,A18,'Test Cases'!L2:L269,"Automated") -> 4 | D18: =COUNTIFS('Test Cases'!B2:B269,A18,'Test Cases'!N2:N269,"Not Run") -> 6 | E18: =COUNTIFS('Test Cases'!B2:B269,A18,'Test Cases'!N2:N269,"Pass") -> 0 | F18: =COUNTIFS('Test Cases'!B2:B269,A18,'Test Cases'!N2:N269,"Fail") -> 0 | G18: =COUNTIFS('Test Cases'!B2:B269,A18,'Test Cases'!N2:N269,"Blocked") -> 0 | H18: =COUNTIFS('Test Cases'!B2:B269,A18,'Test Cases'!N2:N269,"N/A") -> 0
A19: Homepage | B19: =COUNTIF('Test Cases'!B2:B269,A19) -> 33 | C19: =COUNTIFS('Test Cases'!B2:B269,A19,'Test Cases'!L2:L269,"Automated") -> 26 | D19: =COUNTIFS('Test Cases'!B2:B269,A19,'Test Cases'!N2:N269,"Not Run") -> 33 | E19: =COUNTIFS('Test Cases'!B2:B269,A19,'Test Cases'!N2:N269,"Pass") -> 0 | F19: =COUNTIFS('Test Cases'!B2:B269,A19,'Test Cases'!N2:N269,"Fail") -> 0 | G19: =COUNTIFS('Test Cases'!B2:B269,A19,'Test Cases'!N2:N269,"Blocked") -> 0 | H19: =COUNTIFS('Test Cases'!B2:B269,A19,'Test Cases'!N2:N269,"N/A") -> 0
A20: Listing Pages | B20: =COUNTIF('Test Cases'!B2:B269,A20) -> 26 | C20: =COUNTIFS('Test Cases'!B2:B269,A20,'Test Cases'!L2:L269,"Automated") -> 26 | D20: =COUNTIFS('Test Cases'!B2:B269,A20,'Test Cases'!N2:N269,"Not Run") -> 26 | E20: =COUNTIFS('Test Cases'!B2:B269,A20,'Test Cases'!N2:N269,"Pass") -> 0 | F20: =COUNTIFS('Test Cases'!B2:B269,A20,'Test Cases'!N2:N269,"Fail") -> 0 | G20: =COUNTIFS('Test Cases'!B2:B269,A20,'Test Cases'!N2:N269,"Blocked") -> 0 | H20: =COUNTIFS('Test Cases'!B2:B269,A20,'Test Cases'!N2:N269,"N/A") -> 0
A21: Listing Filters | B21: =COUNTIF('Test Cases'!B2:B269,A21) -> 26 | C21: =COUNTIFS('Test Cases'!B2:B269,A21,'Test Cases'!L2:L269,"Automated") -> 17 | D21: =COUNTIFS('Test Cases'!B2:B269,A21,'Test Cases'!N2:N269,"Not Run") -> 26 | E21: =COUNTIFS('Test Cases'!B2:B269,A21,'Test Cases'!N2:N269,"Pass") -> 0 | F21: =COUNTIFS('Test Cases'!B2:B269,A21,'Test Cases'!N2:N269,"Fail") -> 0 | G21: =COUNTIFS('Test Cases'!B2:B269,A21,'Test Cases'!N2:N269,"Blocked") -> 0 | H21: =COUNTIFS('Test Cases'!B2:B269,A21,'Test Cases'!N2:N269,"N/A") -> 0
A22: Detail Pages | B22: =COUNTIF('Test Cases'!B2:B269,A22) -> 16 | C22: =COUNTIFS('Test Cases'!B2:B269,A22,'Test Cases'!L2:L269,"Automated") -> 14 | D22: =COUNTIFS('Test Cases'!B2:B269,A22,'Test Cases'!N2:N269,"Not Run") -> 16 | E22: =COUNTIFS('Test Cases'!B2:B269,A22,'Test Cases'!N2:N269,"Pass") -> 0 | F22: =COUNTIFS('Test Cases'!B2:B269,A22,'Test Cases'!N2:N269,"Fail") -> 0 | G22: =COUNTIFS('Test Cases'!B2:B269,A22,'Test Cases'!N2:N269,"Blocked") -> 0 | H22: =COUNTIFS('Test Cases'!B2:B269,A22,'Test Cases'!N2:N269,"N/A") -> 0
A23: Static & Special Pages | B23: =COUNTIF('Test Cases'!B2:B269,A23) -> 30 | C23: =COUNTIFS('Test Cases'!B2:B269,A23,'Test Cases'!L2:L269,"Automated") -> 27 | D23: =COUNTIFS('Test Cases'!B2:B269,A23,'Test Cases'!N2:N269,"Not Run") -> 30 | E23: =COUNTIFS('Test Cases'!B2:B269,A23,'Test Cases'!N2:N269,"Pass") -> 0 | F23: =COUNTIFS('Test Cases'!B2:B269,A23,'Test Cases'!N2:N269,"Fail") -> 0 | G23: =COUNTIFS('Test Cases'!B2:B269,A23,'Test Cases'!N2:N269,"Blocked") -> 0 | H23: =COUNTIFS('Test Cases'!B2:B269,A23,'Test Cases'!N2:N269,"N/A") -> 0
A24: Footer | B24: =COUNTIF('Test Cases'!B2:B269,A24) -> 5 | C24: =COUNTIFS('Test Cases'!B2:B269,A24,'Test Cases'!L2:L269,"Automated") -> 4 | D24: =COUNTIFS('Test Cases'!B2:B269,A24,'Test Cases'!N2:N269,"Not Run") -> 5 | E24: =COUNTIFS('Test Cases'!B2:B269,A24,'Test Cases'!N2:N269,"Pass") -> 0 | F24: =COUNTIFS('Test Cases'!B2:B269,A24,'Test Cases'!N2:N269,"Fail") -> 0 | G24: =COUNTIFS('Test Cases'!B2:B269,A24,'Test Cases'!N2:N269,"Blocked") -> 0 | H24: =COUNTIFS('Test Cases'!B2:B269,A24,'Test Cases'!N2:N269,"N/A") -> 0
A25: Every Page (automated sweep) | B25: =COUNTIF('Test Cases'!B2:B269,A25) -> 12 | C25: =COUNTIFS('Test Cases'!B2:B269,A25,'Test Cases'!L2:L269,"Automated") -> 12 | D25: =COUNTIFS('Test Cases'!B2:B269,A25,'Test Cases'!N2:N269,"Not Run") -> 12 | E25: =COUNTIFS('Test Cases'!B2:B269,A25,'Test Cases'!N2:N269,"Pass") -> 0 | F25: =COUNTIFS('Test Cases'!B2:B269,A25,'Test Cases'!N2:N269,"Fail") -> 0 | G25: =COUNTIFS('Test Cases'!B2:B269,A25,'Test Cases'!N2:N269,"Blocked") -> 0 | H25: =COUNTIFS('Test Cases'!B2:B269,A25,'Test Cases'!N2:N269,"N/A") -> 0
A26: Responsive & Compatibility | B26: =COUNTIF('Test Cases'!B2:B269,A26) -> 17 | C26: =COUNTIFS('Test Cases'!B2:B269,A26,'Test Cases'!L2:L269,"Automated") -> 5 | D26: =COUNTIFS('Test Cases'!B2:B269,A26,'Test Cases'!N2:N269,"Not Run") -> 17 | E26: =COUNTIFS('Test Cases'!B2:B269,A26,'Test Cases'!N2:N269,"Pass") -> 0 | F26: =COUNTIFS('Test Cases'!B2:B269,A26,'Test Cases'!N2:N269,"Fail") -> 0 | G26: =COUNTIFS('Test Cases'!B2:B269,A26,'Test Cases'!N2:N269,"Blocked") -> 0 | H26: =COUNTIFS('Test Cases'!B2:B269,A26,'Test Cases'!N2:N269,"N/A") -> 0
A27: Accessibility (manual) | B27: =COUNTIF('Test Cases'!B2:B269,A27) -> 7 | C27: =COUNTIFS('Test Cases'!B2:B269,A27,'Test Cases'!L2:L269,"Automated") -> 2 | D27: =COUNTIFS('Test Cases'!B2:B269,A27,'Test Cases'!N2:N269,"Not Run") -> 7 | E27: =COUNTIFS('Test Cases'!B2:B269,A27,'Test Cases'!N2:N269,"Pass") -> 0 | F27: =COUNTIFS('Test Cases'!B2:B269,A27,'Test Cases'!N2:N269,"Fail") -> 0 | G27: =COUNTIFS('Test Cases'!B2:B269,A27,'Test Cases'!N2:N269,"Blocked") -> 0 | H27: =COUNTIFS('Test Cases'!B2:B269,A27,'Test Cases'!N2:N269,"N/A") -> 0
A28: Performance | B28: =COUNTIF('Test Cases'!B2:B269,A28) -> 7 | C28: =COUNTIFS('Test Cases'!B2:B269,A28,'Test Cases'!L2:L269,"Automated") -> 1 | D28: =COUNTIFS('Test Cases'!B2:B269,A28,'Test Cases'!N2:N269,"Not Run") -> 7 | E28: =COUNTIFS('Test Cases'!B2:B269,A28,'Test Cases'!N2:N269,"Pass") -> 0 | F28: =COUNTIFS('Test Cases'!B2:B269,A28,'Test Cases'!N2:N269,"Fail") -> 0 | G28: =COUNTIFS('Test Cases'!B2:B269,A28,'Test Cases'!N2:N269,"Blocked") -> 0 | H28: =COUNTIFS('Test Cases'!B2:B269,A28,'Test Cases'!N2:N269,"N/A") -> 0
A29: SEO | B29: =COUNTIF('Test Cases'!B2:B269,A29) -> 6 | C29: =COUNTIFS('Test Cases'!B2:B269,A29,'Test Cases'!L2:L269,"Automated") -> 4 | D29: =COUNTIFS('Test Cases'!B2:B269,A29,'Test Cases'!N2:N269,"Not Run") -> 6 | E29: =COUNTIFS('Test Cases'!B2:B269,A29,'Test Cases'!N2:N269,"Pass") -> 0 | F29: =COUNTIFS('Test Cases'!B2:B269,A29,'Test Cases'!N2:N269,"Fail") -> 0 | G29: =COUNTIFS('Test Cases'!B2:B269,A29,'Test Cases'!N2:N269,"Blocked") -> 0 | H29: =COUNTIFS('Test Cases'!B2:B269,A29,'Test Cases'!N2:N269,"N/A") -> 0
A30: Error Handling | B30: =COUNTIF('Test Cases'!B2:B269,A30) -> 7 | C30: =COUNTIFS('Test Cases'!B2:B269,A30,'Test Cases'!L2:L269,"Automated") -> 1 | D30: =COUNTIFS('Test Cases'!B2:B269,A30,'Test Cases'!N2:N269,"Not Run") -> 7 | E30: =COUNTIFS('Test Cases'!B2:B269,A30,'Test Cases'!N2:N269,"Pass") -> 0 | F30: =COUNTIFS('Test Cases'!B2:B269,A30,'Test Cases'!N2:N269,"Fail") -> 0 | G30: =COUNTIFS('Test Cases'!B2:B269,A30,'Test Cases'!N2:N269,"Blocked") -> 0 | H30: =COUNTIFS('Test Cases'!B2:B269,A30,'Test Cases'!N2:N269,"N/A") -> 0
A31: Total | B31: =SUM(B14:B30) -> 268 | C31: =SUM(C14:C30) -> 185 | D31: =SUM(D14:D30) -> 268 | E31: =SUM(E14:E30) -> 0 | F31: =SUM(F14:F30) -> 0 | G31: =SUM(G14:G30) -> 0 | H31: =SUM(H14:H30) -> 0
A33: By Type
A34: By Type | B34: Total | C34: Automated | D34: Not Run | E34: Pass | F34: Fail | G34: Blocked | H34: N/A
A35: Accessibility | B35: =COUNTIF('Test Cases'!J2:J269,A35) -> 21 | C35: =COUNTIFS('Test Cases'!J2:J269,A35,'Test Cases'!L2:L269,"Automated") -> 10 | D35: =COUNTIFS('Test Cases'!J2:J269,A35,'Test Cases'!N2:N269,"Not Run") -> 21 | E35: =COUNTIFS('Test Cases'!J2:J269,A35,'Test Cases'!N2:N269,"Pass") -> 0 | F35: =COUNTIFS('Test Cases'!J2:J269,A35,'Test Cases'!N2:N269,"Fail") -> 0 | G35: =COUNTIFS('Test Cases'!J2:J269,A35,'Test Cases'!N2:N269,"Blocked") -> 0 | H35: =COUNTIFS('Test Cases'!J2:J269,A35,'Test Cases'!N2:N269,"N/A") -> 0
A36: Compatibility | B36: =COUNTIF('Test Cases'!J2:J269,A36) -> 7 | C36: =COUNTIFS('Test Cases'!J2:J269,A36,'Test Cases'!L2:L269,"Automated") -> 0 | D36: =COUNTIFS('Test Cases'!J2:J269,A36,'Test Cases'!N2:N269,"Not Run") -> 7 | E36: =COUNTIFS('Test Cases'!J2:J269,A36,'Test Cases'!N2:N269,"Pass") -> 0 | F36: =COUNTIFS('Test Cases'!J2:J269,A36,'Test Cases'!N2:N269,"Fail") -> 0 | G36: =COUNTIFS('Test Cases'!J2:J269,A36,'Test Cases'!N2:N269,"Blocked") -> 0 | H36: =COUNTIFS('Test Cases'!J2:J269,A36,'Test Cases'!N2:N269,"N/A") -> 0
A37: Content | B37: =COUNTIF('Test Cases'!J2:J269,A37) -> 4 | C37: =COUNTIFS('Test Cases'!J2:J269,A37,'Test Cases'!L2:L269,"Automated") -> 1 | D37: =COUNTIFS('Test Cases'!J2:J269,A37,'Test Cases'!N2:N269,"Not Run") -> 4 | E37: =COUNTIFS('Test Cases'!J2:J269,A37,'Test Cases'!N2:N269,"Pass") -> 0 | F37: =COUNTIFS('Test Cases'!J2:J269,A37,'Test Cases'!N2:N269,"Fail") -> 0 | G37: =COUNTIFS('Test Cases'!J2:J269,A37,'Test Cases'!N2:N269,"Blocked") -> 0 | H37: =COUNTIFS('Test Cases'!J2:J269,A37,'Test Cases'!N2:N269,"N/A") -> 0
A38: Edge | B38: =COUNTIF('Test Cases'!J2:J269,A38) -> 41 | C38: =COUNTIFS('Test Cases'!J2:J269,A38,'Test Cases'!L2:L269,"Automated") -> 17 | D38: =COUNTIFS('Test Cases'!J2:J269,A38,'Test Cases'!N2:N269,"Not Run") -> 41 | E38: =COUNTIFS('Test Cases'!J2:J269,A38,'Test Cases'!N2:N269,"Pass") -> 0 | F38: =COUNTIFS('Test Cases'!J2:J269,A38,'Test Cases'!N2:N269,"Fail") -> 0 | G38: =COUNTIFS('Test Cases'!J2:J269,A38,'Test Cases'!N2:N269,"Blocked") -> 0 | H38: =COUNTIFS('Test Cases'!J2:J269,A38,'Test Cases'!N2:N269,"N/A") -> 0
A39: Functional | B39: =COUNTIF('Test Cases'!J2:J269,A39) -> 142 | C39: =COUNTIFS('Test Cases'!J2:J269,A39,'Test Cases'!L2:L269,"Automated") -> 132 | D39: =COUNTIFS('Test Cases'!J2:J269,A39,'Test Cases'!N2:N269,"Not Run") -> 142 | E39: =COUNTIFS('Test Cases'!J2:J269,A39,'Test Cases'!N2:N269,"Pass") -> 0 | F39: =COUNTIFS('Test Cases'!J2:J269,A39,'Test Cases'!N2:N269,"Fail") -> 0 | G39: =COUNTIFS('Test Cases'!J2:J269,A39,'Test Cases'!N2:N269,"Blocked") -> 0 | H39: =COUNTIFS('Test Cases'!J2:J269,A39,'Test Cases'!N2:N269,"N/A") -> 0
A40: Negative | B40: =COUNTIF('Test Cases'!J2:J269,A40) -> 2 | C40: =COUNTIFS('Test Cases'!J2:J269,A40,'Test Cases'!L2:L269,"Automated") -> 0 | D40: =COUNTIFS('Test Cases'!J2:J269,A40,'Test Cases'!N2:N269,"Not Run") -> 2 | E40: =COUNTIFS('Test Cases'!J2:J269,A40,'Test Cases'!N2:N269,"Pass") -> 0 | F40: =COUNTIFS('Test Cases'!J2:J269,A40,'Test Cases'!N2:N269,"Fail") -> 0 | G40: =COUNTIFS('Test Cases'!J2:J269,A40,'Test Cases'!N2:N269,"Blocked") -> 0 | H40: =COUNTIFS('Test Cases'!J2:J269,A40,'Test Cases'!N2:N269,"N/A") -> 0
A41: Performance | B41: =COUNTIF('Test Cases'!J2:J269,A41) -> 7 | C41: =COUNTIFS('Test Cases'!J2:J269,A41,'Test Cases'!L2:L269,"Automated") -> 1 | D41: =COUNTIFS('Test Cases'!J2:J269,A41,'Test Cases'!N2:N269,"Not Run") -> 7 | E41: =COUNTIFS('Test Cases'!J2:J269,A41,'Test Cases'!N2:N269,"Pass") -> 0 | F41: =COUNTIFS('Test Cases'!J2:J269,A41,'Test Cases'!N2:N269,"Fail") -> 0 | G41: =COUNTIFS('Test Cases'!J2:J269,A41,'Test Cases'!N2:N269,"Blocked") -> 0 | H41: =COUNTIFS('Test Cases'!J2:J269,A41,'Test Cases'!N2:N269,"N/A") -> 0
A42: SEO | B42: =COUNTIF('Test Cases'!J2:J269,A42) -> 8 | C42: =COUNTIFS('Test Cases'!J2:J269,A42,'Test Cases'!L2:L269,"Automated") -> 5 | D42: =COUNTIFS('Test Cases'!J2:J269,A42,'Test Cases'!N2:N269,"Not Run") -> 8 | E42: =COUNTIFS('Test Cases'!J2:J269,A42,'Test Cases'!N2:N269,"Pass") -> 0 | F42: =COUNTIFS('Test Cases'!J2:J269,A42,'Test Cases'!N2:N269,"Fail") -> 0 | G42: =COUNTIFS('Test Cases'!J2:J269,A42,'Test Cases'!N2:N269,"Blocked") -> 0 | H42: =COUNTIFS('Test Cases'!J2:J269,A42,'Test Cases'!N2:N269,"N/A") -> 0
A43: Security | B43: =COUNTIF('Test Cases'!J2:J269,A43) -> 8 | C43: =COUNTIFS('Test Cases'!J2:J269,A43,'Test Cases'!L2:L269,"Automated") -> 3 | D43: =COUNTIFS('Test Cases'!J2:J269,A43,'Test Cases'!N2:N269,"Not Run") -> 8 | E43: =COUNTIFS('Test Cases'!J2:J269,A43,'Test Cases'!N2:N269,"Pass") -> 0 | F43: =COUNTIFS('Test Cases'!J2:J269,A43,'Test Cases'!N2:N269,"Fail") -> 0 | G43: =COUNTIFS('Test Cases'!J2:J269,A43,'Test Cases'!N2:N269,"Blocked") -> 0 | H43: =COUNTIFS('Test Cases'!J2:J269,A43,'Test Cases'!N2:N269,"N/A") -> 0
...

Sheet Test Cases
A1: TC ID | B1: Module | C1: Feature | D1: Page / URL | E1: Test Scenario | F1: Preconditions | G1: Test Steps | H1: Test Data | I1: Expected Result | J1: Type | K1: Priority | L1: Automation | M1: Automated In (spec) | N1: Status | O1: Actual Result | P1: Defect ID / Remarks | Q1: Tested By | R1: Test Date
A2: TC-AE-001 | B2: Access & Environment | C2: Basic auth | D2: / | E2: Site asks for credentials on first visit | F2: Fresh incognito window | G2: 1. Open the staging URL | I2: Browser sign-in pop-up appears; page not shown until login | J2: Security | K2: P1 | L2: Manual | N2: Not Run
A3: TC-AE-002 | B3: Access & Environment | C3: Basic auth | D3: / | E3: Valid credentials open the site | F3: Fresh incognito window | G3: 1. Open staging URL 2. Enter valid username/password | H3: Valid staging credentials | I3: Homepage loads (HTTP 200) | J3: Functional | K3: P1 | L3: Automated | M3: tests/crawl/pages.spec.ts | N3: Not Run
A4: TC-AE-003 | B4: Access & Environment | C4: Basic auth | D4: / | E4: NEGATIVE: wrong password is rejected | F4: Fresh incognito window | G4: 1. Open staging URL 2. Enter valid user + wrong password | H4: Wrong password | I4: HTTP 401; pop-up shown again; no content leaked | J4: Negative | K4: P1 | L4: Manual | N4: Not Run
A5: TC-AE-004 | B5: Access & Environment | C5: Basic auth | D5: / | E5: NEGATIVE: cancel the sign-in pop-up | F5: Fresh incognito window | G5: 1. Open staging URL 2. Click Cancel | I5: 401 page; no site content visible | J5: Negative | K5: P2 | L5: Manual | N5: Not Run
A6: TC-AE-005 | B6: Access & Environment | C6: HTTPS | D6: / | E6: HTTP redirects to HTTPS | G6: 1. Open http://stg-rbi.webc.in | I6: Redirects to https://; valid certificate, padlock shown | J6: Security | K6: P1 | L6: Manual | N6: Not Run
A7: TC-AE-006 | B7: Access & Environment | C7: Security headers | D7: / | E7: Security headers present | G7: 1. Open DevTools → Network → document response headers | I7: Strict-Transport-Security, X-Content-Type-Options: nosniff, X-Frame-Options/CSP frame-ancestors, Referrer-Policy present | J7: Security | K7: P2 | L7: Manual | N7: Not Run
A8: TC-AE-007 | B8: Access & Environment | C8: Clickjacking | D8: / | E8: Site cannot be framed by another origin | G8: 1. Create an HTML page with <iframe src="staging URL"> 2. Open it | I8: Frame refuses to load (X-Frame-Options / CSP) | J8: Security | K8: P2 | L8: Manual | N8: Not Run
A9: TC-AE-008 | B9: Access & Environment | C9: Indexing | D9: / | E9: Staging is not indexable by search engines | G9: 1. Check robots meta / X-Robots-Tag on staging | I9: noindex present on staging (production must NOT have it) | J9: SEO | K9: P2 | L9: Manual | N9: Not Run
A10: TC-H-001 | B10: Header | C10: Logo | D10: All pages | E10: Logo visible and links to homepage | F10: Staging login done | G10: 1. Open /press-releases 2. Click RBI logo | I10: Homepage opens | J10: Functional | K10: P1 | L10: Automated | M10: tests/functional/header.spec.ts | N10: Not Run
A11: TC-H-002 | B11: Header | C11: Logo | D11: All pages | E11: Logo image has alt text / accessible name | F11: Staging login done | G11: 1. Inspect logo link | I11: Link has accessible name e.g. "Reserve Bank of India – Home" | J11: Accessibility | K11: P2 | L11: Manual | N11: Not Run
A12: TC-H-003 | B12: Header | C12: Primary nav | D12: All pages | E12: Press Releases link opens listing and is marked current | F12: Staging login done | G12: 1. Click "Press Releases" in header | I12: /press-releases opens; link has aria-current="page" | J12: Functional | K12: P1 | L12: Automated | M12: tests/functional/header.spec.ts | N12: Not Run
A13: TC-H-004 | B13: Header | C13: Mega-menu | D13: All pages | E13: "About RBI" mega-menu opens with links | F13: Staging login done; homepage open | G13: 1. Click "About RBI" | I13: Panel opens; aria-expanded=true; links visible | J13: Functional | K13: P1 | L13: Automated | M13: tests/functional/header.spec.ts | N13: Not Run
A14: TC-H-005 | B14: Header | C14: Mega-menu | D14: All pages | E14: "Functions" mega-menu opens with links | F14: Staging login done; homepage open | G14: 1. Click "Functions" | I14: Panel opens; aria-expanded=true; links visible | J14: Functional | K14: P1 | L14: Automated | M14: tests/functional/header.spec.ts | N14: Not Run
A15: TC-H-006 | B15: Header | C15: Mega-menu | D15: All pages | E15: Every mega-menu link resolves (no 404) | F15: Staging login done; homepage open | G15: 1. Open each mega-menu 2. Visit every link | I15: All links return 200. KNOWN DEFECT: /regulation → 404 | J15: Functional | K15: P1 | L15: Automated | M15: tests/functional/header.spec.ts | N15: Not Run
A16: TC-H-007 | B16: Header | C16: Mega-menu | D16: All pages | E16: Only one mega-menu open at a time | F16: Staging login done; homepage open | G16: 1. Open About RBI 2. Click Functions | I16: About RBI closes; Functions opens | J16: UI | K16: P2 | L16: Automated | M16: tests/functional/header.spec.ts | N16: Not Run
A17: TC-H-008 | B17: Header | C17: Mega-menu | D17: All pages | E17: Escape closes mega-menu and returns focus | F17: Staging login done; homepage open | G17: 1. Open About RBI 2. Press Esc | I17: Menu closes; focus back on "About RBI" | J17: Accessibility | K17: P2 | L17: Automated | M17: tests/functional/header.spec.ts | N17: Not Run
A18: TC-H-009 | B18: Header | C18: Mega-menu | D18: All pages | E18: Click outside closes mega-menu | F18: Staging login done; homepage open | G18: 1. Open Functions 2. Click on page body | I18: Menu closes | J18: UI | K18: P3 | L18: Manual | N18: Not Run
A19: TC-H-010 | B19: Header | C19: Mega-menu | D19: All pages | E19: Keyboard: Tab through mega-menu links | F19: Staging login done; homepage open | G19: 1. Tab to About RBI, press Enter 2. Tab through links | I19: Focus moves through links in order; visible focus ring | J19: Accessibility | K19: P2 | L19: Manual | N19: Not Run
A20: TC-H-011 | B20: Header | C20: Mega-menu | D20: All pages | E20: EDGE: rapid open/close clicking | F20: Staging login done; homepage open | G20: 1. Click About RBI 10 times quickly | I20: Ends in consistent state; no flicker, no JS error | J20: Edge | K20: P3 | L20: Automated | M20: tests/crawl/interactions.spec.ts | N20: Not Run
A21: TC-H-012 | B21: Header | C21: Hamburger menu | D21: All pages | E21: Menu opens and lists all sections | F21: Staging login done; homepage open | G21: 1. Click "Menu" | I21: Full-screen/side menu shows sections; aria-expanded=true | J21: Functional | K21: P1 | L21: Automated | M21: tests/functional/header.spec.ts | N21: Not Run
A22: TC-H-013 | B22: Header | C22: Hamburger menu | D22: All pages | E22: Menu closes with close button and Esc | F22: Staging login done; homepage open | G22: 1. Open Menu 2. Click Close / press Esc | I22: Menu closes; page scroll restored | J22: Functional | K22: P1 | L22: Automated | M22: tests/functional/header.spec.ts | N22: Not Run
A23: TC-H-014 | B23: Header | C23: Hamburger menu | D23: All pages | E23: All hamburger menu links resolve | F23: Staging login done; homepage open | G23: 1. Open Menu 2. Visit every link | I23: All links return 200 | J23: Functional | K23: P1 | L23: Automated | M23: tests/functional/header.spec.ts | N23: Not Run
A24: TC-H-015 | B24: Header | C24: Hamburger menu | D24: All pages | E24: Focus is trapped inside open menu | F24: Staging login done; homepage open | G24: 1. Open Menu 2. Press Tab repeatedly | I24: Focus cycles inside menu; does not reach page behind | J24: Accessibility | K24: P2 | L24: Manual | N24: Not Run
A25: TC-H-016 | B25: Header | C25: Hamburger menu | D25: All pages | E25: Page behind does not scroll while menu open | F25: Staging login done; homepage open | G25: 1. Open Menu 2. Scroll mouse wheel | I25: Only the menu scrolls | J25: UI | K25: P3 | L25: Manual | N25: Not Run
A26: TC-H-017 | B26: Header | C26: Skip link | D26: All pages | E26: First Tab stop is "Skip to main content" | F26: Staging login done; homepage open | G26: 1. Load page 2. Press Tab once | I26: Skip link becomes visible and focused | J26: Accessibility | K26: P2 | L26: Automated | M26: tests/functional/header.spec.ts | N26: Not Run
A27: TC-H-018 | B27: Header | C27: Skip link | D27: All pages | E27: Skip link moves focus into main content | F27: Staging login done; homepage open | G27: 1. Tab to skip link 2. Press Enter | I27: Focus lands on <main>; next Tab goes to first content link | J27: Accessibility | K27: P2 | L27: Automated | M27: tests/functional/header.spec.ts | N27: Not Run
A28: TC-H-019 | B28: Header | C28: Sticky header | D28: All pages | E28: Header stays reachable after scrolling | F28: Staging login done; homepage open | G28: 1. Scroll to bottom | I28: Header/menu button still visible (sticky) or reachable | J28: UI | K28: P3 | L28: Automated | M28: tests/functional/header.spec.ts | N28: Not Run
A29: TC-H-020 | B29: Header | C29: Header layout | D29: All pages | E29: Header consistent across all page templates | F29: Staging login done | G29: 1. Visit home, listing, detail, static, search pages | I29: Same header layout, no shift, logo size consistent | J29: UI | K29: P2 | L29: Manual | N29: Not Run
A30: TC-S-001 | B30: Search | C30: Header search | D30: All pages | E30: Search with valid keyword shows results | F30: Staging login done; homepage open | G30: 1. Type keyword in header search 2. Press Enter | H30: repo rate | I30: /search?q=repo+rate opens; heading "Search result for “repo rate”"; relevant results | J30: Functional | K30: P1 | L30: Automated | M30: tests/functional/search.spec.ts | N30: Not Run
A31: TC-S-002 | B31: Search | C31: Header search | D31: All pages | E31: Search via Search button (not Enter) | F31: Staging login done; homepage open | G31: 1. Type keyword 2. Click magnifier button | H31: inflation | I31: Same results as pressing Enter | J31: Functional | K31: P2 | L31: Manual | N31: Not Run
A32: TC-S-003 | B32: Search | C32: Results | D32: /search | E32: Result count shown and numeric | F32: Staging login done | G32: 1. Search "repo rate" | H32: repo rate | I32: "Show N results" shows a number > 0 | J32: Functional | K32: P2 | L32: Automated | M32: tests/functional/search.spec.ts | N32: Not Run
A33: TC-S-004 | B33: Search | C33: Results | D33: /search | E33: Clicking a result opens the right page | F33: Staging login done | G33: 1. Search 2. Click first result | H33: repo rate | I33: Correct detail page opens with matching title | J33: Functional | K33: P1 | L33: Automated | M33: tests/functional/search.spec.ts | N33: Not Run
A34: TC-S-005 | B34: Search | C34: Results | D34: /search | E34: Results paginate (page 2, next, previous) | F34: Staging login done | G34: 1. Search 2. Click page 2, Next, Previous | H34: repo rate | I34: Results change per page; no duplicates across pages | J34: Functional | K34: P2 | L34: Automated | M34: tests/functional/search.spec.ts | N34: Not Run
A35: TC-S-006 | B35: Search | C35: Results | D35: /search | E35: Items-per-page selector (5/10/20/50) | F35: Staging login done | G35: 1. Search 2. Change items per page | H35: repo rate | I35: Number of results per page matches selection | J35: Functional | K35: P3 | L35: Manual | N35: Not Run
A36: TC-S-007 | B36: Search | C36: Results | D36: /search | E36: Function filter narrows results | F36: Staging login done | G36: 1. Search 2. Tick a function (e.g. About Us) 3. Apply | H36: repo rate | I36: Only results for that function; count updates | J36: Functional | K36: P2 | L36: Manual | N36: Not Run
A37: TC-S-008 | B37: Search | C37: Results | D37: /search | E37: Date filter (month / custom range) narrows results | F37: Staging login done | G37: 1. Search 2. Pick month or custom date range | H37: repo rate; Jan 2020–Dec 2020 | I37: Results only within range | J37: Functional | K37: P2 | L37: Manual | N37: Not Run
A38: TC-S-009 | B38: Search | C38: Results | D38: /search | E38: "Clear all" removes query and filters | F38: Staging login done | G38: 1. Search with filters 2. Click Clear all | I38: Filters/query cleared | J38: Functional | K38: P2 | L38: Automated | M38: tests/functional/search.spec.ts | N38: Not Run
A39: TC-S-010 | B39: Search | C39: Results | D39: /search | E39: Search term is highlighted in results | F39: Staging login done | G39: 1. Search | H39: repo | I39: Matches highlighted (if designed) | J39: UI | K39: P3 | L39: Manual | N39: Not Run
A40: TC-S-011 | B40: Search | C40: Edge | D40: /search | E40: EDGE: no-results message | F40: Staging login done | G40: 1. Search gibberish | H40: zqxwvkjhg123 | I40: "No results for …" message with suggestion; no error | J40: Edge | K40: P1 | L40: Automated | M40: tests/functional/search.spec.ts | N40: Not Run
...

Sheet Known Defects
A1: Defect ID | B1: Category | C1: Area | D1: Description | E1: Pages affected | F1: Severity | G1: URL | H1: Found on | I1: Status | J1: Assigned To | K1: Fixed In Build | L1: Retest Result
A2: D-01 | B2: Broken link | C2: Header → Functions menu | D2: "Regulation" link goes to /regulation → 404 | E2: All pages | F2: High | G2: https://stg-rbi.webc.in/regulation | H2: 27-09-2026 | I2: Open
A3: D-02 | B3: Broken link | C3: Footer | D3: "Opportunities" → 404 | E3: All pages | F3: High | G3: https://stg-rbi.webc.in/opportunities | H3: 27-09-2026 | I3: Open
A4: D-03 | B4: Broken link | C4: Footer | D4: "Important Websites" → 404 | E4: All pages | F4: High | G4: https://stg-rbi.webc.in/important-websites | H4: 27-09-2026 | I4: Open
A5: D-04 | B5: Broken link | C5: Footer | D5: "Bank Holidays" → 404 | E5: All pages | F5: High | G5: https://stg-rbi.webc.in/bank-holidays | H5: 27-09-2026 | I5: Open
A6: D-05 | B6: Broken link | C6: Footer | D6: "RBI Clarifications" → 404 | E6: All pages | F6: High | G6: https://stg-rbi.webc.in/rbi-clarifications | H6: 27-09-2026 | I6: Open
A7: D-06 | B7: Broken link | C7: Footer | D7: "Forms" → 404 | E7: All pages | F7: High | G7: https://stg-rbi.webc.in/forms | H7: 27-09-2026 | I7: Open
A8: D-07 | B8: Broken link | C8: Footer | D8: "RBI's Vision and Values" → 404 | E8: All pages | F8: High | G8: https://stg-rbi.webc.in/about-rbi/vision-and-values | H8: 27-09-2026 | I8: Open
A9: D-08 | B9: Broken link | C9: Site-wide | D9: "RBI Museum" → 404 | E9: All pages | F9: Medium | G9: https://stg-rbi.webc.in/about-us/rbi-museum | H9: 27-09-2026 | I9: Open
A10: D-09 | B10: Broken link | C10: Homepage – Governor's Desk | D10: "Monetary Policy Statements, Governor…" → 404 | E10: / | F10: Medium | G10: https://stg-rbi.webc.in/governor-monetary-policy-statements | H10: 27-09-2026 | I10: Open
A11: D-10 | B11: Soft 404 | C11: Speeches & Media landing | D11: Returns HTTP 200 but renders the "not found" page | E11: /speech-and-media | F11: High | G11: https://stg-rbi.webc.in/speech-and-media | H11: 27-09-2026 | I11: Open
A12: D-11 | B12: Feature missing | C12: Header – Change language | D12: Button has no action; Hindi site /hi returns 404 | E12: All pages | F12: High | G12: https://stg-rbi.webc.in/hi | H12: 27-09-2026 | I12: Open
A13: D-12 | B13: Functional | C13: Homepage – announcement ticker | D13: "Previous announcement" does not move back (Next works) — confirm manually | E13: / | F13: Medium | G13: https://stg-rbi.webc.in/ | H13: 27-09-2026 | I13: Open
... A16: D-15 | B16: Performance | C16: Notifications & Speech listings | D16: HTML response 3–4 s under light concurrency | E16: notifications/*, speech-and-media/* | F16: Medium | G16: https://stg-rbi.webc.in/notifications/draft-directions-re-wise | H16: 27-09-2026 | I16: Open

Sheet Page Inventory
A1: # | B1: Page URL | C1: Template | D1: Interactive features found | E1: Page-health test | F1: Auto-click test | G1: Manual review done?
A2: 1 | B2: https://stg-rbi.webc.in/ | C2: Homepage | D2: Tabs, Accordions/toggles | E2: Automated | F2: Automated
A3: 2 | B3: https://stg-rbi.webc.in/about-us | C3: Static page | D3: Tabs, PDF links | E3: Automated | F3: Automated
A4: 3 | B4: https://stg-rbi.webc.in/about-us/organisation | C4: Static page | D4: Accordions/toggles, PDF links | E4: Automated | F4: Automated
A5: 4 | B5: https://stg-rbi.webc.in/about-us/central-board | C5: Static page | D5: Tables | E5: Automated | F5: Automated
A6: 5 | B6: https://stg-rbi.webc.in/about-us/departments | C6: Static page | D6: — | E6: Automated | F6: Automated
A7: 6 | B7: https://stg-rbi.webc.in/about-us/offices | C7: Static page | D7: Tabs | E7: Automated | F7: Automated
A8: 7 | B8: https://stg-rbi.webc.in/about-us/rbi-history | C8: Static page | D8: Accordions/toggles | E8: Automated | F8: Automated
A9: 8 | B9: https://stg-rbi.webc.in/about-us/communication-policy | C9: Static page with index | D9: On-page index + search, PDF links | E9: Automated | F9: Automated
A10: 9 | B10: https://stg-rbi.webc.in/about-us/sources-of-information | C10: Static page with index | D10: On-page index + search, Tables | E10: Automated | F10: Automated
A11: 10 | B11: https://stg-rbi.webc.in/about-us/media-kit | C11: Static page | D11: — | E11: Automated | F11: Automated
A12: 11 | B12: https://stg-rbi.webc.in/press-releases | C12: Listing with filters | D12: Filters, Pagination, Accordions/toggles, Cards, PDF links | E12: Automated | F12: Automated
A13: 12 | B13: https://stg-rbi.webc.in/banker-to-banks/overview | C13: Static page with index | D13: On-page index + search | E13: Automated | F13: Automated
... A63: 62 | B63: https://stg-rbi.webc.in/statistics/public-debt-statistics | C63: Static page | D63: — | E63: Automated | F63: Automated
B65: Menu/footer pages listed here; detail pages (≈60,000 press releases etc.) are sampled by the crawler (MAX_PER_SECTION).
